[2025-05-18T03:55:34.231+0000] {taskinstance.py:1159} INFO - Dependencies all met for dep_context=non-requeueable deps ti=<TaskInstance: elt_and_dbt.run_elt_script manual__2025-05-18T03:55:31.512014+00:00 [queued]>
[2025-05-18T03:55:34.235+0000] {taskinstance.py:1159} INFO - Dependencies all met for dep_context=requeueable deps ti=<TaskInstance: elt_and_dbt.run_elt_script manual__2025-05-18T03:55:31.512014+00:00 [queued]>
[2025-05-18T03:55:34.235+0000] {taskinstance.py:1361} INFO - Starting attempt 1 of 1
[2025-05-18T03:55:34.240+0000] {taskinstance.py:1382} INFO - Executing <Task(PythonOperator): run_elt_script> on 2025-05-18 03:55:31.512014+00:00
[2025-05-18T03:55:34.242+0000] {standard_task_runner.py:57} INFO - Started process 57 to run task
[2025-05-18T03:55:34.245+0000] {standard_task_runner.py:84} INFO - Running: ['***', 'tasks', 'run', 'elt_and_dbt', 'run_elt_script', 'manual__2025-05-18T03:55:31.512014+00:00', '--job-id', '2', '--raw', '--subdir', 'DAGS_FOLDER/elt_dag.py', '--cfg-path', '/tmp/tmp33v5jzst']
[2025-05-18T03:55:34.250+0000] {standard_task_runner.py:85} INFO - Job 2: Subtask run_elt_script
[2025-05-18T03:55:34.431+0000] {task_command.py:416} INFO - Running <TaskInstance: elt_and_dbt.run_elt_script manual__2025-05-18T03:55:31.512014+00:00 [running]> on host e5d7a1e6bcbf
[2025-05-18T03:55:34.504+0000] {taskinstance.py:1662} INFO - Exporting env vars: AIRFLOW_CTX_DAG_OWNER='***' AIRFLOW_CTX_DAG_ID='elt_and_dbt' AIRFLOW_CTX_TASK_ID='run_elt_script' AIRFLOW_CTX_EXECUTION_DATE='2025-05-18T03:55:31.512014+00:00' AIRFLOW_CTX_TRY_NUMBER='1' AIRFLOW_CTX_DAG_RUN_ID='manual__2025-05-18T03:55:31.512014+00:00'
[2025-05-18T03:55:34.575+0000] {taskinstance.py:1937} ERROR - Task failed with exception
Traceback (most recent call last):
  File "/home/airflow/.local/lib/python3.8/site-packages/airflow/operators/python.py", line 192, in execute
    return_value = self.execute_callable()
  File "/home/airflow/.local/lib/python3.8/site-packages/airflow/operators/python.py", line 209, in execute_callable
    return self.python_callable(*self.op_args, **self.op_kwargs)
  File "/opt/airflow/dags/elt_dag.py", line 24, in run_elt_script
    raise Exception(f"Script failed with error: {result.stderr}")
Exception: Script failed with error: python: can't open file '/opt/***/elt_script/elt_script.py': [Errno 2] No such file or directory

[2025-05-18T03:55:34.584+0000] {taskinstance.py:1400} INFO - Marking task as FAILED. dag_id=elt_and_dbt, task_id=run_elt_script, execution_date=20250518T035531, start_date=20250518T035534, end_date=20250518T035534
[2025-05-18T03:55:34.590+0000] {standard_task_runner.py:104} ERROR - Failed to execute job 2 for task run_elt_script (Script failed with error: python: can't open file '/opt/***/elt_script/elt_script.py': [Errno 2] No such file or directory
; 57)
[2025-05-18T03:55:34.615+0000] {local_task_job_runner.py:228} INFO - Task exited with return code 1
[2025-05-18T03:55:34.625+0000] {taskinstance.py:2778} INFO - 0 downstream tasks scheduled from follow-on schedule check
